{
 "cells": [
  {
   "cell_type": "code",
   "execution_count": 2,
   "metadata": {
    "_cell_guid": "b1076dfc-b9ad-4769-8c92-a6c4dae69d19",
    "_uuid": "8f2839f25d086af736a60e9eeb907d3b93b6e0e5",
    "execution": {
     "iopub.execute_input": "2021-11-16T18:21:31.566335Z",
     "iopub.status.busy": "2021-11-16T18:21:31.565435Z",
     "iopub.status.idle": "2021-11-16T18:21:46.940942Z",
     "shell.execute_reply": "2021-11-16T18:21:46.939864Z",
     "shell.execute_reply.started": "2021-11-16T18:21:31.566289Z"
    }
   },
   "outputs": [
    {
     "name": "stdout",
     "output_type": "stream",
     "text": [
      "^C\n",
      "Note: you may need to restart the kernel to use updated packages.\n"
     ]
    }
   ],
   "source": [
    "pip install plot_keras_history"
   ]
  },
  {
   "cell_type": "code",
   "execution_count": null,
   "metadata": {
    "execution": {
     "iopub.execute_input": "2021-11-16T18:25:13.580902Z",
     "iopub.status.busy": "2021-11-16T18:25:13.580587Z",
     "iopub.status.idle": "2021-11-16T18:25:13.587654Z",
     "shell.execute_reply": "2021-11-16T18:25:13.586892Z",
     "shell.execute_reply.started": "2021-11-16T18:25:13.580867Z"
    }
   },
   "outputs": [
    {
     "name": "stdout",
     "output_type": "stream",
     "text": [
      "Collecting plot_keras_history\n",
      "  Downloading plot_keras_history-1.1.29.tar.gz (9.2 kB)\n",
      "  Preparing metadata (setup.py): started\n",
      "  Preparing metadata (setup.py): finished with status 'done'\n",
      "Requirement already satisfied: matplotlib in c:\\users\\vinay\\anaconda3\\lib\\site-packages (from plot_keras_history) (3.4.3)\n",
      "Requirement already satisfied: pandas in c:\\users\\vinay\\anaconda3\\lib\\site-packages (from plot_keras_history) (1.3.3)\n",
      "Requirement already satisfied: scipy in c:\\users\\vinay\\anaconda3\\lib\\site-packages (from plot_keras_history) (1.7.1)\n",
      "Collecting sanitize_ml_labels\n",
      "  Downloading sanitize_ml_labels-1.0.26.tar.gz (6.4 kB)\n",
      "  Preparing metadata (setup.py): started\n",
      "  Preparing metadata (setup.py): finished with status 'done'\n",
      "Requirement already satisfied: pyparsing>=2.2.1 in c:\\users\\vinay\\anaconda3\\lib\\site-packages (from matplotlib->plot_keras_history) (2.4.7)\n",
      "Requirement already satisfied: kiwisolver>=1.0.1 in c:\\users\\vinay\\anaconda3\\lib\\site-packages (from matplotlib->plot_keras_history) (1.3.2)\n",
      "Requirement already satisfied: cycler>=0.10 in c:\\users\\vinay\\anaconda3\\lib\\site-packages (from matplotlib->plot_keras_history) (0.10.0)\n",
      "Requirement already satisfied: numpy>=1.16 in c:\\users\\vinay\\anaconda3\\lib\\site-packages (from matplotlib->plot_keras_history) (1.21.2)\n",
      "Requirement already satisfied: python-dateutil>=2.7 in c:\\users\\vinay\\anaconda3\\lib\\site-packages (from matplotlib->plot_keras_history) (2.8.2)\n",
      "Requirement already satisfied: pillow>=6.2.0 in c:\\users\\vinay\\anaconda3\\lib\\site-packages (from matplotlib->plot_keras_history) (8.3.1)\n",
      "Requirement already satisfied: pytz>=2017.3 in c:\\users\\vinay\\anaconda3\\lib\\site-packages (from pandas->plot_keras_history) (2021.3)\n",
      "Collecting compress_json\n",
      "  Downloading compress_json-1.0.4.tar.gz (4.7 kB)\n",
      "  Preparing metadata (setup.py): started\n",
      "  Preparing metadata (setup.py): finished with status 'done'\n",
      "Requirement already satisfied: six in c:\\users\\vinay\\anaconda3\\lib\\site-packages (from cycler>=0.10->matplotlib->plot_keras_history) (1.16.0)\n",
      "Building wheels for collected packages: plot-keras-history, sanitize-ml-labels, compress-json\n",
      "  Building wheel for plot-keras-history (setup.py): started\n",
      "  Building wheel for plot-keras-history (setup.py): finished with status 'done'\n",
      "  Created wheel for plot-keras-history: filename=plot_keras_history-1.1.29-py3-none-any.whl size=8613 sha256=d2eb932a706667248f3090d69e1930df89dfa03803f64529ababd77d65b2edc3\n",
      "  Stored in directory: c:\\users\\vinay\\appdata\\local\\pip\\cache\\wheels\\a0\\fa\\68\\0c3f71f298b99366c7efc3fd98294c58f75b58bd5b91a87eb4\n",
      "  Building wheel for sanitize-ml-labels (setup.py): started\n",
      "  Building wheel for sanitize-ml-labels (setup.py): finished with status 'done'\n",
      "  Created wheel for sanitize-ml-labels: filename=sanitize_ml_labels-1.0.26-py3-none-any.whl size=7612 sha256=baeee8d4e1206860924cc5a6d25b46c836f685a9e45421e5a0a3d2d301b4af41\n",
      "  Stored in directory: c:\\users\\vinay\\appdata\\local\\pip\\cache\\wheels\\d8\\ec\\8b\\d63a91f7060f8b72a790de44492ecf6aee0b5fe1d7b56380be\n",
      "  Building wheel for compress-json (setup.py): started\n",
      "  Building wheel for compress-json (setup.py): finished with status 'done'\n",
      "  Created wheel for compress-json: filename=compress_json-1.0.4-py3-none-any.whl size=4585 sha256=d1dd5387034079b08ac509aa1708ad968a8bc002f455f5772bedd02c95ff62ba\n",
      "  Stored in directory: c:\\users\\vinay\\appdata\\local\\pip\\cache\\wheels\\57\\b7\\6d\\7f4da6ca958ba18b00ea85ba46a5dbfae8f08b992c1466b49b\n",
      "Successfully built plot-keras-history sanitize-ml-labels compress-json\n",
      "Installing collected packages: compress-json, sanitize-ml-labels, plot-keras-history\n",
      "Successfully installed compress-json-1.0.4 plot-keras-history-1.1.29 sanitize-ml-labels-1.0.26\n"
     ]
    },
    {
     "name": "stderr",
     "output_type": "stream",
     "text": [
      "ERROR:root:Internal Python error in the inspect module.\n",
      "Below is the traceback from this internal error.\n",
      "\n",
      "ERROR:root:Internal Python error in the inspect module.\n",
      "Below is the traceback from this internal error.\n",
      "\n"
     ]
    },
    {
     "name": "stdout",
     "output_type": "stream",
     "text": [
      "Traceback (most recent call last):\n",
      "  File \"C:\\Users\\vinay\\Anaconda3\\lib\\site-packages\\IPython\\core\\interactiveshell.py\", line 3444, in run_code\n",
      "    exec(code_obj, self.user_global_ns, self.user_ns)\n",
      "  File \"C:\\Users\\vinay\\AppData\\Local\\Temp/ipykernel_46104/2016672178.py\", line 5, in <module>\n",
      "    import keras\n",
      "  File \"C:\\Users\\vinay\\Anaconda3\\lib\\site-packages\\keras\\__init__.py\", line 3, in <module>\n",
      "    from tensorflow.keras.layers.experimental.preprocessing import RandomRotation\n",
      "  File \"C:\\Users\\vinay\\Anaconda3\\lib\\site-packages\\tensorflow\\__init__.py\", line 41, in <module>\n",
      "    from tensorflow.python.tools import module_util as _module_util\n",
      "  File \"C:\\Users\\vinay\\Anaconda3\\lib\\site-packages\\tensorflow\\python\\__init__.py\", line 45, in <module>\n",
      "    from tensorflow.python import data\n",
      "  File \"C:\\Users\\vinay\\Anaconda3\\lib\\site-packages\\tensorflow\\python\\data\\__init__.py\", line 25, in <module>\n",
      "    from tensorflow.python.data import experimental\n",
      "  File \"C:\\Users\\vinay\\Anaconda3\\lib\\site-packages\\tensorflow\\python\\data\\experimental\\__init__.py\", line 96, in <module>\n",
      "    from tensorflow.python.data.experimental import service\n",
      "  File \"C:\\Users\\vinay\\Anaconda3\\lib\\site-packages\\tensorflow\\python\\data\\experimental\\service\\__init__.py\", line 21, in <module>\n",
      "    from tensorflow.python.data.experimental.ops.data_service_ops import distribute\n",
      "  File \"C:\\Users\\vinay\\Anaconda3\\lib\\site-packages\\tensorflow\\python\\data\\experimental\\ops\\data_service_ops.py\", line 28, in <module>\n",
      "    from tensorflow.python.data.ops import dataset_ops\n",
      "  File \"C:\\Users\\vinay\\Anaconda3\\lib\\site-packages\\tensorflow\\python\\data\\ops\\dataset_ops.py\", line 36, in <module>\n",
      "    from tensorflow.python.data.experimental.ops import stats_options\n",
      "  File \"C:\\Users\\vinay\\Anaconda3\\lib\\site-packages\\tensorflow\\python\\data\\experimental\\ops\\stats_options.py\", line 22, in <module>\n",
      "    from tensorflow.python.data.experimental.ops import stats_aggregator\n",
      "  File \"C:\\Users\\vinay\\Anaconda3\\lib\\site-packages\\tensorflow\\python\\data\\experimental\\ops\\stats_aggregator.py\", line 23, in <module>\n",
      "    from tensorflow.python.ops import summary_ops_v2\n",
      "  File \"<frozen importlib._bootstrap>\", line 991, in _find_and_load\n",
      "  File \"<frozen importlib._bootstrap>\", line 971, in _find_and_load_unlocked\n",
      "  File \"<frozen importlib._bootstrap>\", line 914, in _find_spec\n",
      "  File \"<frozen importlib._bootstrap_external>\", line 1407, in find_spec\n",
      "  File \"<frozen importlib._bootstrap_external>\", line 1379, in _get_spec\n",
      "  File \"<frozen importlib._bootstrap_external>\", line 1539, in find_spec\n",
      "  File \"<frozen importlib._bootstrap_external>\", line 156, in _path_isfile\n",
      "  File \"<frozen importlib._bootstrap_external>\", line 148, in _path_is_mode_type\n",
      "  File \"<frozen importlib._bootstrap_external>\", line 142, in _path_stat\n",
      "KeyboardInterrupt\n",
      "\n",
      "During handling of the above exception, another exception occurred:\n",
      "\n",
      "Traceback (most recent call last):\n",
      "  File \"C:\\Users\\vinay\\Anaconda3\\lib\\site-packages\\IPython\\core\\interactiveshell.py\", line 2064, in showtraceback\n",
      "    stb = value._render_traceback_()\n",
      "AttributeError: 'KeyboardInterrupt' object has no attribute '_render_traceback_'\n",
      "\n",
      "During handling of the above exception, another exception occurred:\n",
      "\n",
      "Traceback (most recent call last):\n",
      "  File \"C:\\Users\\vinay\\Anaconda3\\lib\\site-packages\\IPython\\core\\ultratb.py\", line 1101, in get_records\n",
      "    return _fixed_getinnerframes(etb, number_of_lines_of_context, tb_offset)\n",
      "  File \"C:\\Users\\vinay\\Anaconda3\\lib\\site-packages\\IPython\\core\\ultratb.py\", line 248, in wrapped\n",
      "    return f(*args, **kwargs)\n",
      "  File \"C:\\Users\\vinay\\Anaconda3\\lib\\site-packages\\IPython\\core\\ultratb.py\", line 281, in _fixed_getinnerframes\n",
      "    records = fix_frame_records_filenames(inspect.getinnerframes(etb, context))\n",
      "  File \"C:\\Users\\vinay\\Anaconda3\\lib\\inspect.py\", line 1515, in getinnerframes\n",
      "    frameinfo = (tb.tb_frame,) + getframeinfo(tb, context)\n",
      "  File \"C:\\Users\\vinay\\Anaconda3\\lib\\inspect.py\", line 1473, in getframeinfo\n",
      "    filename = getsourcefile(frame) or getfile(frame)\n",
      "  File \"C:\\Users\\vinay\\Anaconda3\\lib\\inspect.py\", line 708, in getsourcefile\n",
      "    if getattr(getmodule(object, filename), '__loader__', None) is not None:\n",
      "  File \"C:\\Users\\vinay\\Anaconda3\\lib\\inspect.py\", line 754, in getmodule\n",
      "    os.path.realpath(f)] = module.__name__\n",
      "  File \"C:\\Users\\vinay\\Anaconda3\\lib\\ntpath.py\", line 664, in realpath\n",
      "    if _getfinalpathname(spath) == path:\n",
      "KeyboardInterrupt\n"
     ]
    },
    {
     "name": "stderr",
     "output_type": "stream",
     "text": [
      "ERROR:root:Internal Python error in the inspect module.\n",
      "Below is the traceback from this internal error.\n",
      "\n"
     ]
    },
    {
     "name": "stdout",
     "output_type": "stream",
     "text": [
      "Traceback (most recent call last):\n",
      "  File \"C:\\Users\\vinay\\Anaconda3\\lib\\site-packages\\IPython\\core\\interactiveshell.py\", line 3444, in run_code\n",
      "    exec(code_obj, self.user_global_ns, self.user_ns)\n",
      "  File \"C:\\Users\\vinay\\AppData\\Local\\Temp/ipykernel_46104/2016672178.py\", line 5, in <module>\n",
      "    import keras\n",
      "  File \"C:\\Users\\vinay\\Anaconda3\\lib\\site-packages\\keras\\__init__.py\", line 3, in <module>\n",
      "    from tensorflow.keras.layers.experimental.preprocessing import RandomRotation\n",
      "  File \"C:\\Users\\vinay\\Anaconda3\\lib\\site-packages\\tensorflow\\__init__.py\", line 41, in <module>\n",
      "    from tensorflow.python.tools import module_util as _module_util\n",
      "  File \"C:\\Users\\vinay\\Anaconda3\\lib\\site-packages\\tensorflow\\python\\__init__.py\", line 45, in <module>\n",
      "    from tensorflow.python import data\n",
      "  File \"C:\\Users\\vinay\\Anaconda3\\lib\\site-packages\\tensorflow\\python\\data\\__init__.py\", line 25, in <module>\n",
      "    from tensorflow.python.data import experimental\n",
      "  File \"C:\\Users\\vinay\\Anaconda3\\lib\\site-packages\\tensorflow\\python\\data\\experimental\\__init__.py\", line 96, in <module>\n",
      "    from tensorflow.python.data.experimental import service\n",
      "  File \"C:\\Users\\vinay\\Anaconda3\\lib\\site-packages\\tensorflow\\python\\data\\experimental\\service\\__init__.py\", line 21, in <module>\n",
      "    from tensorflow.python.data.experimental.ops.data_service_ops import distribute\n",
      "  File \"C:\\Users\\vinay\\Anaconda3\\lib\\site-packages\\tensorflow\\python\\data\\experimental\\ops\\data_service_ops.py\", line 28, in <module>\n",
      "    from tensorflow.python.data.ops import dataset_ops\n",
      "  File \"C:\\Users\\vinay\\Anaconda3\\lib\\site-packages\\tensorflow\\python\\data\\ops\\dataset_ops.py\", line 36, in <module>\n",
      "    from tensorflow.python.data.experimental.ops import stats_options\n",
      "  File \"C:\\Users\\vinay\\Anaconda3\\lib\\site-packages\\tensorflow\\python\\data\\experimental\\ops\\stats_options.py\", line 22, in <module>\n",
      "    from tensorflow.python.data.experimental.ops import stats_aggregator\n",
      "  File \"C:\\Users\\vinay\\Anaconda3\\lib\\site-packages\\tensorflow\\python\\data\\experimental\\ops\\stats_aggregator.py\", line 23, in <module>\n",
      "    from tensorflow.python.ops import summary_ops_v2\n",
      "  File \"<frozen importlib._bootstrap>\", line 991, in _find_and_load\n",
      "  File \"<frozen importlib._bootstrap>\", line 971, in _find_and_load_unlocked\n",
      "  File \"<frozen importlib._bootstrap>\", line 914, in _find_spec\n",
      "  File \"<frozen importlib._bootstrap_external>\", line 1407, in find_spec\n",
      "  File \"<frozen importlib._bootstrap_external>\", line 1379, in _get_spec\n",
      "  File \"<frozen importlib._bootstrap_external>\", line 1539, in find_spec\n",
      "  File \"<frozen importlib._bootstrap_external>\", line 156, in _path_isfile\n",
      "  File \"<frozen importlib._bootstrap_external>\", line 148, in _path_is_mode_type\n",
      "  File \"<frozen importlib._bootstrap_external>\", line 142, in _path_stat\n",
      "KeyboardInterrupt\n",
      "\n",
      "During handling of the above exception, another exception occurred:\n",
      "\n",
      "Traceback (most recent call last):\n",
      "  File \"C:\\Users\\vinay\\Anaconda3\\lib\\site-packages\\IPython\\core\\interactiveshell.py\", line 2064, in showtraceback\n",
      "    stb = value._render_traceback_()\n",
      "AttributeError: 'KeyboardInterrupt' object has no attribute '_render_traceback_'\n",
      "\n",
      "During handling of the above exception, another exception occurred:\n",
      "\n",
      "Traceback (most recent call last):\n",
      "  File \"C:\\Users\\vinay\\Anaconda3\\lib\\site-packages\\IPython\\core\\interactiveshell.py\", line 3364, in run_ast_nodes\n",
      "    if (await self.run_code(code, result,  async_=asy)):\n",
      "  File \"C:\\Users\\vinay\\Anaconda3\\lib\\site-packages\\IPython\\core\\interactiveshell.py\", line 3461, in run_code\n",
      "    self.showtraceback(running_compiled_code=True)\n",
      "  File \"C:\\Users\\vinay\\Anaconda3\\lib\\site-packages\\IPython\\core\\interactiveshell.py\", line 2066, in showtraceback\n",
      "    stb = self.InteractiveTB.structured_traceback(etype,\n",
      "  File \"C:\\Users\\vinay\\Anaconda3\\lib\\site-packages\\IPython\\core\\ultratb.py\", line 1367, in structured_traceback\n",
      "    return FormattedTB.structured_traceback(\n",
      "  File \"C:\\Users\\vinay\\Anaconda3\\lib\\site-packages\\IPython\\core\\ultratb.py\", line 1267, in structured_traceback\n",
      "    return VerboseTB.structured_traceback(\n",
      "  File \"C:\\Users\\vinay\\Anaconda3\\lib\\site-packages\\IPython\\core\\ultratb.py\", line 1124, in structured_traceback\n",
      "    formatted_exception = self.format_exception_as_a_whole(etype, evalue, etb, number_of_lines_of_context,\n",
      "  File \"C:\\Users\\vinay\\Anaconda3\\lib\\site-packages\\IPython\\core\\ultratb.py\", line 1082, in format_exception_as_a_whole\n",
      "    last_unique, recursion_repeat = find_recursion(orig_etype, evalue, records)\n",
      "  File \"C:\\Users\\vinay\\Anaconda3\\lib\\site-packages\\IPython\\core\\ultratb.py\", line 382, in find_recursion\n",
      "    return len(records), 0\n",
      "TypeError: object of type 'NoneType' has no len()\n",
      "\n",
      "During handling of the above exception, another exception occurred:\n",
      "\n",
      "Traceback (most recent call last):\n",
      "  File \"C:\\Users\\vinay\\Anaconda3\\lib\\site-packages\\IPython\\core\\interactiveshell.py\", line 2064, in showtraceback\n",
      "    stb = value._render_traceback_()\n",
      "AttributeError: 'TypeError' object has no attribute '_render_traceback_'\n",
      "\n",
      "During handling of the above exception, another exception occurred:\n",
      "\n",
      "Traceback (most recent call last):\n",
      "  File \"C:\\Users\\vinay\\Anaconda3\\lib\\site-packages\\IPython\\core\\ultratb.py\", line 1101, in get_records\n",
      "    return _fixed_getinnerframes(etb, number_of_lines_of_context, tb_offset)\n",
      "  File \"C:\\Users\\vinay\\Anaconda3\\lib\\site-packages\\IPython\\core\\ultratb.py\", line 248, in wrapped\n",
      "    return f(*args, **kwargs)\n",
      "  File \"C:\\Users\\vinay\\Anaconda3\\lib\\site-packages\\IPython\\core\\ultratb.py\", line 281, in _fixed_getinnerframes\n",
      "    records = fix_frame_records_filenames(inspect.getinnerframes(etb, context))\n",
      "  File \"C:\\Users\\vinay\\Anaconda3\\lib\\inspect.py\", line 1515, in getinnerframes\n",
      "    frameinfo = (tb.tb_frame,) + getframeinfo(tb, context)\n",
      "  File \"C:\\Users\\vinay\\Anaconda3\\lib\\inspect.py\", line 1473, in getframeinfo\n",
      "    filename = getsourcefile(frame) or getfile(frame)\n",
      "  File \"C:\\Users\\vinay\\Anaconda3\\lib\\inspect.py\", line 708, in getsourcefile\n",
      "    if getattr(getmodule(object, filename), '__loader__', None) is not None:\n",
      "  File \"C:\\Users\\vinay\\Anaconda3\\lib\\inspect.py\", line 754, in getmodule\n",
      "    os.path.realpath(f)] = module.__name__\n",
      "  File \"C:\\Users\\vinay\\Anaconda3\\lib\\ntpath.py\", line 664, in realpath\n",
      "    if _getfinalpathname(spath) == path:\n",
      "KeyboardInterrupt\n",
      "Traceback (most recent call last):\n",
      "  File \"C:\\Users\\vinay\\Anaconda3\\lib\\site-packages\\IPython\\core\\interactiveshell.py\", line 3444, in run_code\n",
      "    exec(code_obj, self.user_global_ns, self.user_ns)\n",
      "  File \"C:\\Users\\vinay\\AppData\\Local\\Temp/ipykernel_46104/2016672178.py\", line 5, in <module>\n",
      "    import keras\n",
      "  File \"C:\\Users\\vinay\\Anaconda3\\lib\\site-packages\\keras\\__init__.py\", line 3, in <module>\n",
      "    from tensorflow.keras.layers.experimental.preprocessing import RandomRotation\n",
      "  File \"C:\\Users\\vinay\\Anaconda3\\lib\\site-packages\\tensorflow\\__init__.py\", line 41, in <module>\n",
      "    from tensorflow.python.tools import module_util as _module_util\n",
      "  File \"C:\\Users\\vinay\\Anaconda3\\lib\\site-packages\\tensorflow\\python\\__init__.py\", line 45, in <module>\n",
      "    from tensorflow.python import data\n",
      "  File \"C:\\Users\\vinay\\Anaconda3\\lib\\site-packages\\tensorflow\\python\\data\\__init__.py\", line 25, in <module>\n",
      "    from tensorflow.python.data import experimental\n",
      "  File \"C:\\Users\\vinay\\Anaconda3\\lib\\site-packages\\tensorflow\\python\\data\\experimental\\__init__.py\", line 96, in <module>\n",
      "    from tensorflow.python.data.experimental import service\n",
      "  File \"C:\\Users\\vinay\\Anaconda3\\lib\\site-packages\\tensorflow\\python\\data\\experimental\\service\\__init__.py\", line 21, in <module>\n",
      "    from tensorflow.python.data.experimental.ops.data_service_ops import distribute\n",
      "  File \"C:\\Users\\vinay\\Anaconda3\\lib\\site-packages\\tensorflow\\python\\data\\experimental\\ops\\data_service_ops.py\", line 28, in <module>\n",
      "    from tensorflow.python.data.ops import dataset_ops\n",
      "  File \"C:\\Users\\vinay\\Anaconda3\\lib\\site-packages\\tensorflow\\python\\data\\ops\\dataset_ops.py\", line 36, in <module>\n",
      "    from tensorflow.python.data.experimental.ops import stats_options\n",
      "  File \"C:\\Users\\vinay\\Anaconda3\\lib\\site-packages\\tensorflow\\python\\data\\experimental\\ops\\stats_options.py\", line 22, in <module>\n",
      "    from tensorflow.python.data.experimental.ops import stats_aggregator\n",
      "  File \"C:\\Users\\vinay\\Anaconda3\\lib\\site-packages\\tensorflow\\python\\data\\experimental\\ops\\stats_aggregator.py\", line 23, in <module>\n",
      "    from tensorflow.python.ops import summary_ops_v2\n",
      "  File \"<frozen importlib._bootstrap>\", line 991, in _find_and_load\n",
      "  File \"<frozen importlib._bootstrap>\", line 971, in _find_and_load_unlocked\n",
      "  File \"<frozen importlib._bootstrap>\", line 914, in _find_spec\n",
      "  File \"<frozen importlib._bootstrap_external>\", line 1407, in find_spec\n",
      "  File \"<frozen importlib._bootstrap_external>\", line 1379, in _get_spec\n",
      "  File \"<frozen importlib._bootstrap_external>\", line 1539, in find_spec\n",
      "  File \"<frozen importlib._bootstrap_external>\", line 156, in _path_isfile\n",
      "  File \"<frozen importlib._bootstrap_external>\", line 148, in _path_is_mode_type\n",
      "  File \"<frozen importlib._bootstrap_external>\", line 142, in _path_stat\n",
      "KeyboardInterrupt\n",
      "\n",
      "During handling of the above exception, another exception occurred:\n",
      "\n",
      "Traceback (most recent call last):\n",
      "  File \"C:\\Users\\vinay\\Anaconda3\\lib\\site-packages\\IPython\\core\\interactiveshell.py\", line 2064, in showtraceback\n",
      "    stb = value._render_traceback_()\n",
      "AttributeError: 'KeyboardInterrupt' object has no attribute '_render_traceback_'\n",
      "\n",
      "During handling of the above exception, another exception occurred:\n",
      "\n",
      "Traceback (most recent call last):\n",
      "  File \"C:\\Users\\vinay\\Anaconda3\\lib\\site-packages\\IPython\\core\\interactiveshell.py\", line 3364, in run_ast_nodes\n",
      "    if (await self.run_code(code, result,  async_=asy)):\n",
      "  File \"C:\\Users\\vinay\\Anaconda3\\lib\\site-packages\\IPython\\core\\interactiveshell.py\", line 3461, in run_code\n",
      "    self.showtraceback(running_compiled_code=True)\n",
      "  File \"C:\\Users\\vinay\\Anaconda3\\lib\\site-packages\\IPython\\core\\interactiveshell.py\", line 2066, in showtraceback\n",
      "    stb = self.InteractiveTB.structured_traceback(etype,\n",
      "  File \"C:\\Users\\vinay\\Anaconda3\\lib\\site-packages\\IPython\\core\\ultratb.py\", line 1367, in structured_traceback\n",
      "    return FormattedTB.structured_traceback(\n",
      "  File \"C:\\Users\\vinay\\Anaconda3\\lib\\site-packages\\IPython\\core\\ultratb.py\", line 1267, in structured_traceback\n",
      "    return VerboseTB.structured_traceback(\n",
      "  File \"C:\\Users\\vinay\\Anaconda3\\lib\\site-packages\\IPython\\core\\ultratb.py\", line 1124, in structured_traceback\n",
      "    formatted_exception = self.format_exception_as_a_whole(etype, evalue, etb, number_of_lines_of_context,\n",
      "  File \"C:\\Users\\vinay\\Anaconda3\\lib\\site-packages\\IPython\\core\\ultratb.py\", line 1082, in format_exception_as_a_whole\n",
      "    last_unique, recursion_repeat = find_recursion(orig_etype, evalue, records)\n",
      "  File \"C:\\Users\\vinay\\Anaconda3\\lib\\site-packages\\IPython\\core\\ultratb.py\", line 382, in find_recursion\n",
      "    return len(records), 0\n",
      "TypeError: object of type 'NoneType' has no len()\n",
      "\n",
      "During handling of the above exception, another exception occurred:\n",
      "\n",
      "Traceback (most recent call last):\n",
      "  File \"C:\\Users\\vinay\\Anaconda3\\lib\\site-packages\\IPython\\core\\interactiveshell.py\", line 2064, in showtraceback\n",
      "    stb = value._render_traceback_()\n",
      "AttributeError: 'TypeError' object has no attribute '_render_traceback_'\n",
      "\n",
      "During handling of the above exception, another exception occurred:\n",
      "\n",
      "Traceback (most recent call last):\n",
      "  File \"C:\\Users\\vinay\\Anaconda3\\lib\\site-packages\\IPython\\core\\interactiveshell.py\", line 2947, in _run_cell\n",
      "    return runner(coro)\n",
      "  File \"C:\\Users\\vinay\\Anaconda3\\lib\\site-packages\\IPython\\core\\async_helpers.py\", line 68, in _pseudo_sync_runner\n",
      "    coro.send(None)\n",
      "  File \"C:\\Users\\vinay\\Anaconda3\\lib\\site-packages\\IPython\\core\\interactiveshell.py\", line 3172, in run_cell_async\n",
      "    has_raised = await self.run_ast_nodes(code_ast.body, cell_name,\n",
      "  File \"C:\\Users\\vinay\\Anaconda3\\lib\\site-packages\\IPython\\core\\interactiveshell.py\", line 3383, in run_ast_nodes\n",
      "    self.showtraceback()\n",
      "  File \"C:\\Users\\vinay\\Anaconda3\\lib\\site-packages\\IPython\\core\\interactiveshell.py\", line 2066, in showtraceback\n",
      "    stb = self.InteractiveTB.structured_traceback(etype,\n",
      "  File \"C:\\Users\\vinay\\Anaconda3\\lib\\site-packages\\IPython\\core\\ultratb.py\", line 1367, in structured_traceback\n",
      "    return FormattedTB.structured_traceback(\n",
      "  File \"C:\\Users\\vinay\\Anaconda3\\lib\\site-packages\\IPython\\core\\ultratb.py\", line 1267, in structured_traceback\n",
      "    return VerboseTB.structured_traceback(\n",
      "  File \"C:\\Users\\vinay\\Anaconda3\\lib\\site-packages\\IPython\\core\\ultratb.py\", line 1142, in structured_traceback\n",
      "    formatted_exceptions += self.format_exception_as_a_whole(etype, evalue, etb, lines_of_context,\n",
      "  File \"C:\\Users\\vinay\\Anaconda3\\lib\\site-packages\\IPython\\core\\ultratb.py\", line 1082, in format_exception_as_a_whole\n",
      "    last_unique, recursion_repeat = find_recursion(orig_etype, evalue, records)\n",
      "  File \"C:\\Users\\vinay\\Anaconda3\\lib\\site-packages\\IPython\\core\\ultratb.py\", line 382, in find_recursion\n",
      "    return len(records), 0\n",
      "TypeError: object of type 'NoneType' has no len()\n",
      "\n",
      "During handling of the above exception, another exception occurred:\n",
      "\n",
      "Traceback (most recent call last):\n",
      "  File \"C:\\Users\\vinay\\Anaconda3\\lib\\site-packages\\IPython\\core\\interactiveshell.py\", line 2064, in showtraceback\n",
      "    stb = value._render_traceback_()\n",
      "AttributeError: 'TypeError' object has no attribute '_render_traceback_'\n",
      "\n",
      "During handling of the above exception, another exception occurred:\n",
      "\n",
      "Traceback (most recent call last):\n",
      "  File \"C:\\Users\\vinay\\Anaconda3\\lib\\site-packages\\IPython\\core\\ultratb.py\", line 1101, in get_records\n",
      "    return _fixed_getinnerframes(etb, number_of_lines_of_context, tb_offset)\n",
      "  File \"C:\\Users\\vinay\\Anaconda3\\lib\\site-packages\\IPython\\core\\ultratb.py\", line 248, in wrapped\n",
      "    return f(*args, **kwargs)\n",
      "  File \"C:\\Users\\vinay\\Anaconda3\\lib\\site-packages\\IPython\\core\\ultratb.py\", line 281, in _fixed_getinnerframes\n",
      "    records = fix_frame_records_filenames(inspect.getinnerframes(etb, context))\n",
      "  File \"C:\\Users\\vinay\\Anaconda3\\lib\\inspect.py\", line 1515, in getinnerframes\n",
      "    frameinfo = (tb.tb_frame,) + getframeinfo(tb, context)\n",
      "  File \"C:\\Users\\vinay\\Anaconda3\\lib\\inspect.py\", line 1473, in getframeinfo\n",
      "    filename = getsourcefile(frame) or getfile(frame)\n",
      "  File \"C:\\Users\\vinay\\Anaconda3\\lib\\inspect.py\", line 708, in getsourcefile\n",
      "    if getattr(getmodule(object, filename), '__loader__', None) is not None:\n",
      "  File \"C:\\Users\\vinay\\Anaconda3\\lib\\inspect.py\", line 754, in getmodule\n",
      "    os.path.realpath(f)] = module.__name__\n",
      "  File \"C:\\Users\\vinay\\Anaconda3\\lib\\ntpath.py\", line 647, in realpath\n",
      "    path = _getfinalpathname(path)\n",
      "KeyboardInterrupt\n"
     ]
    }
   ],
   "source": [
    "import pandas as pd\n",
    "import numpy as np\n",
    "import seaborn as sns\n",
    "import matplotlib.pyplot as plt\n",
    "import keras\n",
    "from keras.models import Sequential\n",
    "import matplotlib.pyplot as plt\n",
    "from keras.layers import Dense, Activation, Embedding, Flatten, GlobalMaxPool1D, Dropout, Conv1D,MaxPooling1D\n",
    "from keras.callbacks import ReduceLROnPlateau, EarlyStopping, ModelCheckpoint\n",
    "from keras.losses import binary_crossentropy\n",
    "from tensorflow.keras.optimizers import Adam, SGD\n",
    "from keras.utils.vis_utils import plot_model\n",
    "from plot_keras_history import plot_history\n",
    "\n",
    "import random\n",
    "from sklearn.datasets import make_classification\n",
    "from sklearn.neighbors import NearestNeighbors"
   ]
  },
  {
   "cell_type": "code",
   "execution_count": 3,
   "metadata": {
    "execution": {
     "iopub.execute_input": "2021-11-16T18:26:37.828160Z",
     "iopub.status.busy": "2021-11-16T18:26:37.827847Z",
     "iopub.status.idle": "2021-11-16T18:26:40.140340Z",
     "shell.execute_reply": "2021-11-16T18:26:40.139439Z",
     "shell.execute_reply.started": "2021-11-16T18:26:37.828119Z"
    }
   },
   "outputs": [
    {
     "name": "stderr",
     "output_type": "stream",
     "text": [
      "ERROR:root:Internal Python error in the inspect module.\n",
      "Below is the traceback from this internal error.\n",
      "\n"
     ]
    },
    {
     "name": "stdout",
     "output_type": "stream",
     "text": [
      "ERROR! Session/line number was not unique in database. History logging moved to new session 325\n",
      "Traceback (most recent call last):\n",
      "  File \"C:\\Users\\vinay\\Anaconda3\\lib\\site-packages\\IPython\\core\\interactiveshell.py\", line 3444, in run_code\n",
      "    exec(code_obj, self.user_global_ns, self.user_ns)\n",
      "  File \"C:\\Users\\vinay\\AppData\\Local\\Temp/ipykernel_46104/1988453957.py\", line 1, in <module>\n",
      "    x_train = pd.read_csv(r'../input/satdrec/Train_Features.csv', index_col=0)\n",
      "  File \"C:\\Users\\vinay\\Anaconda3\\lib\\site-packages\\pandas\\util\\_decorators.py\", line 311, in wrapper\n",
      "    return func(*args, **kwargs)\n",
      "  File \"C:\\Users\\vinay\\Anaconda3\\lib\\site-packages\\pandas\\io\\parsers\\readers.py\", line 586, in read_csv\n",
      "    return _read(filepath_or_buffer, kwds)\n",
      "  File \"C:\\Users\\vinay\\Anaconda3\\lib\\site-packages\\pandas\\io\\parsers\\readers.py\", line 482, in _read\n",
      "    parser = TextFileReader(filepath_or_buffer, **kwds)\n",
      "  File \"C:\\Users\\vinay\\Anaconda3\\lib\\site-packages\\pandas\\io\\parsers\\readers.py\", line 811, in __init__\n",
      "    self._engine = self._make_engine(self.engine)\n",
      "  File \"C:\\Users\\vinay\\Anaconda3\\lib\\site-packages\\pandas\\io\\parsers\\readers.py\", line 1040, in _make_engine\n",
      "    return mapping[engine](self.f, **self.options)  # type: ignore[call-arg]\n",
      "  File \"C:\\Users\\vinay\\Anaconda3\\lib\\site-packages\\pandas\\io\\parsers\\c_parser_wrapper.py\", line 51, in __init__\n",
      "    self._open_handles(src, kwds)\n",
      "  File \"C:\\Users\\vinay\\Anaconda3\\lib\\site-packages\\pandas\\io\\parsers\\base_parser.py\", line 222, in _open_handles\n",
      "    self.handles = get_handle(\n",
      "  File \"C:\\Users\\vinay\\Anaconda3\\lib\\site-packages\\pandas\\io\\common.py\", line 702, in get_handle\n",
      "    handle = open(\n",
      "FileNotFoundError: [Errno 2] No such file or directory: '../input/satdrec/Train_Features.csv'\n",
      "\n",
      "During handling of the above exception, another exception occurred:\n",
      "\n",
      "Traceback (most recent call last):\n",
      "  File \"C:\\Users\\vinay\\Anaconda3\\lib\\site-packages\\IPython\\core\\interactiveshell.py\", line 2064, in showtraceback\n",
      "    stb = value._render_traceback_()\n",
      "AttributeError: 'FileNotFoundError' object has no attribute '_render_traceback_'\n",
      "\n",
      "During handling of the above exception, another exception occurred:\n",
      "\n",
      "Traceback (most recent call last):\n",
      "  File \"C:\\Users\\vinay\\Anaconda3\\lib\\site-packages\\IPython\\core\\ultratb.py\", line 1101, in get_records\n",
      "    return _fixed_getinnerframes(etb, number_of_lines_of_context, tb_offset)\n",
      "  File \"C:\\Users\\vinay\\Anaconda3\\lib\\site-packages\\IPython\\core\\ultratb.py\", line 248, in wrapped\n",
      "    return f(*args, **kwargs)\n",
      "  File \"C:\\Users\\vinay\\Anaconda3\\lib\\site-packages\\IPython\\core\\ultratb.py\", line 281, in _fixed_getinnerframes\n",
      "    records = fix_frame_records_filenames(inspect.getinnerframes(etb, context))\n",
      "  File \"C:\\Users\\vinay\\Anaconda3\\lib\\inspect.py\", line 1515, in getinnerframes\n",
      "    frameinfo = (tb.tb_frame,) + getframeinfo(tb, context)\n",
      "  File \"C:\\Users\\vinay\\Anaconda3\\lib\\inspect.py\", line 1473, in getframeinfo\n",
      "    filename = getsourcefile(frame) or getfile(frame)\n",
      "  File \"C:\\Users\\vinay\\Anaconda3\\lib\\inspect.py\", line 708, in getsourcefile\n",
      "    if getattr(getmodule(object, filename), '__loader__', None) is not None:\n",
      "  File \"C:\\Users\\vinay\\Anaconda3\\lib\\inspect.py\", line 754, in getmodule\n",
      "    os.path.realpath(f)] = module.__name__\n",
      "  File \"C:\\Users\\vinay\\Anaconda3\\lib\\ntpath.py\", line 664, in realpath\n",
      "    if _getfinalpathname(spath) == path:\n",
      "KeyboardInterrupt\n"
     ]
    },
    {
     "ename": "TypeError",
     "evalue": "object of type 'NoneType' has no len()",
     "output_type": "error",
     "traceback": [
      "\u001b[1;31m---------------------------------------------------------------------------\u001b[0m",
      "\u001b[1;31mFileNotFoundError\u001b[0m                         Traceback (most recent call last)",
      "    \u001b[1;31m[... skipping hidden 1 frame]\u001b[0m\n",
      "\u001b[1;32m~\\AppData\\Local\\Temp/ipykernel_46104/1988453957.py\u001b[0m in \u001b[0;36m<module>\u001b[1;34m\u001b[0m\n\u001b[1;32m----> 1\u001b[1;33m \u001b[0mx_train\u001b[0m \u001b[1;33m=\u001b[0m \u001b[0mpd\u001b[0m\u001b[1;33m.\u001b[0m\u001b[0mread_csv\u001b[0m\u001b[1;33m(\u001b[0m\u001b[1;34mr'../input/satdrec/Train_Features.csv'\u001b[0m\u001b[1;33m,\u001b[0m \u001b[0mindex_col\u001b[0m\u001b[1;33m=\u001b[0m\u001b[1;36m0\u001b[0m\u001b[1;33m)\u001b[0m\u001b[1;33m\u001b[0m\u001b[1;33m\u001b[0m\u001b[0m\n\u001b[0m\u001b[0;32m      2\u001b[0m \u001b[0my_train\u001b[0m \u001b[1;33m=\u001b[0m \u001b[0mpd\u001b[0m\u001b[1;33m.\u001b[0m\u001b[0mread_csv\u001b[0m\u001b[1;33m(\u001b[0m\u001b[1;34mr'../input/satdrec/Train_Labels.csv'\u001b[0m\u001b[1;33m,\u001b[0m \u001b[0mindex_col\u001b[0m\u001b[1;33m=\u001b[0m\u001b[1;36m0\u001b[0m\u001b[1;33m)\u001b[0m\u001b[1;33m\u001b[0m\u001b[1;33m\u001b[0m\u001b[0m\n\u001b[0;32m      3\u001b[0m \u001b[0mx_test\u001b[0m \u001b[1;33m=\u001b[0m \u001b[0mpd\u001b[0m\u001b[1;33m.\u001b[0m\u001b[0mread_csv\u001b[0m\u001b[1;33m(\u001b[0m\u001b[1;34mr'../input/satdrec/Test_Features.csv'\u001b[0m\u001b[1;33m,\u001b[0m \u001b[0mindex_col\u001b[0m\u001b[1;33m=\u001b[0m\u001b[1;36m0\u001b[0m\u001b[1;33m)\u001b[0m\u001b[1;33m\u001b[0m\u001b[1;33m\u001b[0m\u001b[0m\n",
      "\u001b[1;32m~\\Anaconda3\\lib\\site-packages\\pandas\\util\\_decorators.py\u001b[0m in \u001b[0;36mwrapper\u001b[1;34m(*args, **kwargs)\u001b[0m\n\u001b[0;32m    310\u001b[0m                 )\n\u001b[1;32m--> 311\u001b[1;33m             \u001b[1;32mreturn\u001b[0m \u001b[0mfunc\u001b[0m\u001b[1;33m(\u001b[0m\u001b[1;33m*\u001b[0m\u001b[0margs\u001b[0m\u001b[1;33m,\u001b[0m \u001b[1;33m**\u001b[0m\u001b[0mkwargs\u001b[0m\u001b[1;33m)\u001b[0m\u001b[1;33m\u001b[0m\u001b[1;33m\u001b[0m\u001b[0m\n\u001b[0m\u001b[0;32m    312\u001b[0m \u001b[1;33m\u001b[0m\u001b[0m\n",
      "\u001b[1;32m~\\Anaconda3\\lib\\site-packages\\pandas\\io\\parsers\\readers.py\u001b[0m in \u001b[0;36mread_csv\u001b[1;34m(filepath_or_buffer, sep, delimiter, header, names, index_col, usecols, squeeze, prefix, mangle_dupe_cols, dtype, engine, converters, true_values, false_values, skipinitialspace, skiprows, skipfooter, nrows, na_values, keep_default_na, na_filter, verbose, skip_blank_lines, parse_dates, infer_datetime_format, keep_date_col, date_parser, dayfirst, cache_dates, iterator, chunksize, compression, thousands, decimal, lineterminator, quotechar, quoting, doublequote, escapechar, comment, encoding, encoding_errors, dialect, error_bad_lines, warn_bad_lines, on_bad_lines, delim_whitespace, low_memory, memory_map, float_precision, storage_options)\u001b[0m\n\u001b[0;32m    585\u001b[0m \u001b[1;33m\u001b[0m\u001b[0m\n\u001b[1;32m--> 586\u001b[1;33m     \u001b[1;32mreturn\u001b[0m \u001b[0m_read\u001b[0m\u001b[1;33m(\u001b[0m\u001b[0mfilepath_or_buffer\u001b[0m\u001b[1;33m,\u001b[0m \u001b[0mkwds\u001b[0m\u001b[1;33m)\u001b[0m\u001b[1;33m\u001b[0m\u001b[1;33m\u001b[0m\u001b[0m\n\u001b[0m\u001b[0;32m    587\u001b[0m \u001b[1;33m\u001b[0m\u001b[0m\n",
      "\u001b[1;32m~\\Anaconda3\\lib\\site-packages\\pandas\\io\\parsers\\readers.py\u001b[0m in \u001b[0;36m_read\u001b[1;34m(filepath_or_buffer, kwds)\u001b[0m\n\u001b[0;32m    481\u001b[0m     \u001b[1;31m# Create the parser.\u001b[0m\u001b[1;33m\u001b[0m\u001b[1;33m\u001b[0m\u001b[1;33m\u001b[0m\u001b[0m\n\u001b[1;32m--> 482\u001b[1;33m     \u001b[0mparser\u001b[0m \u001b[1;33m=\u001b[0m \u001b[0mTextFileReader\u001b[0m\u001b[1;33m(\u001b[0m\u001b[0mfilepath_or_buffer\u001b[0m\u001b[1;33m,\u001b[0m \u001b[1;33m**\u001b[0m\u001b[0mkwds\u001b[0m\u001b[1;33m)\u001b[0m\u001b[1;33m\u001b[0m\u001b[1;33m\u001b[0m\u001b[0m\n\u001b[0m\u001b[0;32m    483\u001b[0m \u001b[1;33m\u001b[0m\u001b[0m\n",
      "\u001b[1;32m~\\Anaconda3\\lib\\site-packages\\pandas\\io\\parsers\\readers.py\u001b[0m in \u001b[0;36m__init__\u001b[1;34m(self, f, engine, **kwds)\u001b[0m\n\u001b[0;32m    810\u001b[0m \u001b[1;33m\u001b[0m\u001b[0m\n\u001b[1;32m--> 811\u001b[1;33m         \u001b[0mself\u001b[0m\u001b[1;33m.\u001b[0m\u001b[0m_engine\u001b[0m \u001b[1;33m=\u001b[0m \u001b[0mself\u001b[0m\u001b[1;33m.\u001b[0m\u001b[0m_make_engine\u001b[0m\u001b[1;33m(\u001b[0m\u001b[0mself\u001b[0m\u001b[1;33m.\u001b[0m\u001b[0mengine\u001b[0m\u001b[1;33m)\u001b[0m\u001b[1;33m\u001b[0m\u001b[1;33m\u001b[0m\u001b[0m\n\u001b[0m\u001b[0;32m    812\u001b[0m \u001b[1;33m\u001b[0m\u001b[0m\n",
      "\u001b[1;32m~\\Anaconda3\\lib\\site-packages\\pandas\\io\\parsers\\readers.py\u001b[0m in \u001b[0;36m_make_engine\u001b[1;34m(self, engine)\u001b[0m\n\u001b[0;32m   1039\u001b[0m         \u001b[1;31m# error: Too many arguments for \"ParserBase\"\u001b[0m\u001b[1;33m\u001b[0m\u001b[1;33m\u001b[0m\u001b[1;33m\u001b[0m\u001b[0m\n\u001b[1;32m-> 1040\u001b[1;33m         \u001b[1;32mreturn\u001b[0m \u001b[0mmapping\u001b[0m\u001b[1;33m[\u001b[0m\u001b[0mengine\u001b[0m\u001b[1;33m]\u001b[0m\u001b[1;33m(\u001b[0m\u001b[0mself\u001b[0m\u001b[1;33m.\u001b[0m\u001b[0mf\u001b[0m\u001b[1;33m,\u001b[0m \u001b[1;33m**\u001b[0m\u001b[0mself\u001b[0m\u001b[1;33m.\u001b[0m\u001b[0moptions\u001b[0m\u001b[1;33m)\u001b[0m  \u001b[1;31m# type: ignore[call-arg]\u001b[0m\u001b[1;33m\u001b[0m\u001b[1;33m\u001b[0m\u001b[0m\n\u001b[0m\u001b[0;32m   1041\u001b[0m \u001b[1;33m\u001b[0m\u001b[0m\n",
      "\u001b[1;32m~\\Anaconda3\\lib\\site-packages\\pandas\\io\\parsers\\c_parser_wrapper.py\u001b[0m in \u001b[0;36m__init__\u001b[1;34m(self, src, **kwds)\u001b[0m\n\u001b[0;32m     50\u001b[0m         \u001b[1;31m# open handles\u001b[0m\u001b[1;33m\u001b[0m\u001b[1;33m\u001b[0m\u001b[1;33m\u001b[0m\u001b[0m\n\u001b[1;32m---> 51\u001b[1;33m         \u001b[0mself\u001b[0m\u001b[1;33m.\u001b[0m\u001b[0m_open_handles\u001b[0m\u001b[1;33m(\u001b[0m\u001b[0msrc\u001b[0m\u001b[1;33m,\u001b[0m \u001b[0mkwds\u001b[0m\u001b[1;33m)\u001b[0m\u001b[1;33m\u001b[0m\u001b[1;33m\u001b[0m\u001b[0m\n\u001b[0m\u001b[0;32m     52\u001b[0m         \u001b[1;32massert\u001b[0m \u001b[0mself\u001b[0m\u001b[1;33m.\u001b[0m\u001b[0mhandles\u001b[0m \u001b[1;32mis\u001b[0m \u001b[1;32mnot\u001b[0m \u001b[1;32mNone\u001b[0m\u001b[1;33m\u001b[0m\u001b[1;33m\u001b[0m\u001b[0m\n",
      "\u001b[1;32m~\\Anaconda3\\lib\\site-packages\\pandas\\io\\parsers\\base_parser.py\u001b[0m in \u001b[0;36m_open_handles\u001b[1;34m(self, src, kwds)\u001b[0m\n\u001b[0;32m    221\u001b[0m         \"\"\"\n\u001b[1;32m--> 222\u001b[1;33m         self.handles = get_handle(\n\u001b[0m\u001b[0;32m    223\u001b[0m             \u001b[0msrc\u001b[0m\u001b[1;33m,\u001b[0m\u001b[1;33m\u001b[0m\u001b[1;33m\u001b[0m\u001b[0m\n",
      "\u001b[1;32m~\\Anaconda3\\lib\\site-packages\\pandas\\io\\common.py\u001b[0m in \u001b[0;36mget_handle\u001b[1;34m(path_or_buf, mode, encoding, compression, memory_map, is_text, errors, storage_options)\u001b[0m\n\u001b[0;32m    701\u001b[0m             \u001b[1;31m# Encoding\u001b[0m\u001b[1;33m\u001b[0m\u001b[1;33m\u001b[0m\u001b[1;33m\u001b[0m\u001b[0m\n\u001b[1;32m--> 702\u001b[1;33m             handle = open(\n\u001b[0m\u001b[0;32m    703\u001b[0m                 \u001b[0mhandle\u001b[0m\u001b[1;33m,\u001b[0m\u001b[1;33m\u001b[0m\u001b[1;33m\u001b[0m\u001b[0m\n",
      "\u001b[1;31mFileNotFoundError\u001b[0m: [Errno 2] No such file or directory: '../input/satdrec/Train_Features.csv'",
      "\nDuring handling of the above exception, another exception occurred:\n",
      "\u001b[1;31mAttributeError\u001b[0m                            Traceback (most recent call last)",
      "\u001b[1;32m~\\Anaconda3\\lib\\site-packages\\IPython\\core\\interactiveshell.py\u001b[0m in \u001b[0;36mshowtraceback\u001b[1;34m(self, exc_tuple, filename, tb_offset, exception_only, running_compiled_code)\u001b[0m\n\u001b[0;32m   2063\u001b[0m                         \u001b[1;31m# in the engines. This should return a list of strings.\u001b[0m\u001b[1;33m\u001b[0m\u001b[1;33m\u001b[0m\u001b[1;33m\u001b[0m\u001b[0m\n\u001b[1;32m-> 2064\u001b[1;33m                         \u001b[0mstb\u001b[0m \u001b[1;33m=\u001b[0m \u001b[0mvalue\u001b[0m\u001b[1;33m.\u001b[0m\u001b[0m_render_traceback_\u001b[0m\u001b[1;33m(\u001b[0m\u001b[1;33m)\u001b[0m\u001b[1;33m\u001b[0m\u001b[1;33m\u001b[0m\u001b[0m\n\u001b[0m\u001b[0;32m   2065\u001b[0m                     \u001b[1;32mexcept\u001b[0m \u001b[0mException\u001b[0m\u001b[1;33m:\u001b[0m\u001b[1;33m\u001b[0m\u001b[1;33m\u001b[0m\u001b[0m\n",
      "\u001b[1;31mAttributeError\u001b[0m: 'FileNotFoundError' object has no attribute '_render_traceback_'",
      "\nDuring handling of the above exception, another exception occurred:\n",
      "\u001b[1;31mTypeError\u001b[0m                                 Traceback (most recent call last)",
      "    \u001b[1;31m[... skipping hidden 1 frame]\u001b[0m\n",
      "\u001b[1;32m~\\Anaconda3\\lib\\site-packages\\IPython\\core\\interactiveshell.py\u001b[0m in \u001b[0;36mshowtraceback\u001b[1;34m(self, exc_tuple, filename, tb_offset, exception_only, running_compiled_code)\u001b[0m\n\u001b[0;32m   2064\u001b[0m                         \u001b[0mstb\u001b[0m \u001b[1;33m=\u001b[0m \u001b[0mvalue\u001b[0m\u001b[1;33m.\u001b[0m\u001b[0m_render_traceback_\u001b[0m\u001b[1;33m(\u001b[0m\u001b[1;33m)\u001b[0m\u001b[1;33m\u001b[0m\u001b[1;33m\u001b[0m\u001b[0m\n\u001b[0;32m   2065\u001b[0m                     \u001b[1;32mexcept\u001b[0m \u001b[0mException\u001b[0m\u001b[1;33m:\u001b[0m\u001b[1;33m\u001b[0m\u001b[1;33m\u001b[0m\u001b[0m\n\u001b[1;32m-> 2066\u001b[1;33m                         stb = self.InteractiveTB.structured_traceback(etype,\n\u001b[0m\u001b[0;32m   2067\u001b[0m                                             value, tb, tb_offset=tb_offset)\n\u001b[0;32m   2068\u001b[0m \u001b[1;33m\u001b[0m\u001b[0m\n",
      "\u001b[1;32m~\\Anaconda3\\lib\\site-packages\\IPython\\core\\ultratb.py\u001b[0m in \u001b[0;36mstructured_traceback\u001b[1;34m(self, etype, value, tb, tb_offset, number_of_lines_of_context)\u001b[0m\n\u001b[0;32m   1365\u001b[0m         \u001b[1;32melse\u001b[0m\u001b[1;33m:\u001b[0m\u001b[1;33m\u001b[0m\u001b[1;33m\u001b[0m\u001b[0m\n\u001b[0;32m   1366\u001b[0m             \u001b[0mself\u001b[0m\u001b[1;33m.\u001b[0m\u001b[0mtb\u001b[0m \u001b[1;33m=\u001b[0m \u001b[0mtb\u001b[0m\u001b[1;33m\u001b[0m\u001b[1;33m\u001b[0m\u001b[0m\n\u001b[1;32m-> 1367\u001b[1;33m         return FormattedTB.structured_traceback(\n\u001b[0m\u001b[0;32m   1368\u001b[0m             self, etype, value, tb, tb_offset, number_of_lines_of_context)\n\u001b[0;32m   1369\u001b[0m \u001b[1;33m\u001b[0m\u001b[0m\n",
      "\u001b[1;32m~\\Anaconda3\\lib\\site-packages\\IPython\\core\\ultratb.py\u001b[0m in \u001b[0;36mstructured_traceback\u001b[1;34m(self, etype, value, tb, tb_offset, number_of_lines_of_context)\u001b[0m\n\u001b[0;32m   1265\u001b[0m         \u001b[1;32mif\u001b[0m \u001b[0mmode\u001b[0m \u001b[1;32min\u001b[0m \u001b[0mself\u001b[0m\u001b[1;33m.\u001b[0m\u001b[0mverbose_modes\u001b[0m\u001b[1;33m:\u001b[0m\u001b[1;33m\u001b[0m\u001b[1;33m\u001b[0m\u001b[0m\n\u001b[0;32m   1266\u001b[0m             \u001b[1;31m# Verbose modes need a full traceback\u001b[0m\u001b[1;33m\u001b[0m\u001b[1;33m\u001b[0m\u001b[1;33m\u001b[0m\u001b[0m\n\u001b[1;32m-> 1267\u001b[1;33m             return VerboseTB.structured_traceback(\n\u001b[0m\u001b[0;32m   1268\u001b[0m                 \u001b[0mself\u001b[0m\u001b[1;33m,\u001b[0m \u001b[0metype\u001b[0m\u001b[1;33m,\u001b[0m \u001b[0mvalue\u001b[0m\u001b[1;33m,\u001b[0m \u001b[0mtb\u001b[0m\u001b[1;33m,\u001b[0m \u001b[0mtb_offset\u001b[0m\u001b[1;33m,\u001b[0m \u001b[0mnumber_of_lines_of_context\u001b[0m\u001b[1;33m\u001b[0m\u001b[1;33m\u001b[0m\u001b[0m\n\u001b[0;32m   1269\u001b[0m             )\n",
      "\u001b[1;32m~\\Anaconda3\\lib\\site-packages\\IPython\\core\\ultratb.py\u001b[0m in \u001b[0;36mstructured_traceback\u001b[1;34m(self, etype, evalue, etb, tb_offset, number_of_lines_of_context)\u001b[0m\n\u001b[0;32m   1122\u001b[0m         \u001b[1;34m\"\"\"Return a nice text document describing the traceback.\"\"\"\u001b[0m\u001b[1;33m\u001b[0m\u001b[1;33m\u001b[0m\u001b[0m\n\u001b[0;32m   1123\u001b[0m \u001b[1;33m\u001b[0m\u001b[0m\n\u001b[1;32m-> 1124\u001b[1;33m         formatted_exception = self.format_exception_as_a_whole(etype, evalue, etb, number_of_lines_of_context,\n\u001b[0m\u001b[0;32m   1125\u001b[0m                                                                tb_offset)\n\u001b[0;32m   1126\u001b[0m \u001b[1;33m\u001b[0m\u001b[0m\n",
      "\u001b[1;32m~\\Anaconda3\\lib\\site-packages\\IPython\\core\\ultratb.py\u001b[0m in \u001b[0;36mformat_exception_as_a_whole\u001b[1;34m(self, etype, evalue, etb, number_of_lines_of_context, tb_offset)\u001b[0m\n\u001b[0;32m   1080\u001b[0m \u001b[1;33m\u001b[0m\u001b[0m\n\u001b[0;32m   1081\u001b[0m \u001b[1;33m\u001b[0m\u001b[0m\n\u001b[1;32m-> 1082\u001b[1;33m         \u001b[0mlast_unique\u001b[0m\u001b[1;33m,\u001b[0m \u001b[0mrecursion_repeat\u001b[0m \u001b[1;33m=\u001b[0m \u001b[0mfind_recursion\u001b[0m\u001b[1;33m(\u001b[0m\u001b[0morig_etype\u001b[0m\u001b[1;33m,\u001b[0m \u001b[0mevalue\u001b[0m\u001b[1;33m,\u001b[0m \u001b[0mrecords\u001b[0m\u001b[1;33m)\u001b[0m\u001b[1;33m\u001b[0m\u001b[1;33m\u001b[0m\u001b[0m\n\u001b[0m\u001b[0;32m   1083\u001b[0m \u001b[1;33m\u001b[0m\u001b[0m\n\u001b[0;32m   1084\u001b[0m         \u001b[0mframes\u001b[0m \u001b[1;33m=\u001b[0m \u001b[0mself\u001b[0m\u001b[1;33m.\u001b[0m\u001b[0mformat_records\u001b[0m\u001b[1;33m(\u001b[0m\u001b[0mrecords\u001b[0m\u001b[1;33m,\u001b[0m \u001b[0mlast_unique\u001b[0m\u001b[1;33m,\u001b[0m \u001b[0mrecursion_repeat\u001b[0m\u001b[1;33m)\u001b[0m\u001b[1;33m\u001b[0m\u001b[1;33m\u001b[0m\u001b[0m\n",
      "\u001b[1;32m~\\Anaconda3\\lib\\site-packages\\IPython\\core\\ultratb.py\u001b[0m in \u001b[0;36mfind_recursion\u001b[1;34m(etype, value, records)\u001b[0m\n\u001b[0;32m    380\u001b[0m     \u001b[1;31m# first frame (from in to out) that looks different.\u001b[0m\u001b[1;33m\u001b[0m\u001b[1;33m\u001b[0m\u001b[1;33m\u001b[0m\u001b[0m\n\u001b[0;32m    381\u001b[0m     \u001b[1;32mif\u001b[0m \u001b[1;32mnot\u001b[0m \u001b[0mis_recursion_error\u001b[0m\u001b[1;33m(\u001b[0m\u001b[0metype\u001b[0m\u001b[1;33m,\u001b[0m \u001b[0mvalue\u001b[0m\u001b[1;33m,\u001b[0m \u001b[0mrecords\u001b[0m\u001b[1;33m)\u001b[0m\u001b[1;33m:\u001b[0m\u001b[1;33m\u001b[0m\u001b[1;33m\u001b[0m\u001b[0m\n\u001b[1;32m--> 382\u001b[1;33m         \u001b[1;32mreturn\u001b[0m \u001b[0mlen\u001b[0m\u001b[1;33m(\u001b[0m\u001b[0mrecords\u001b[0m\u001b[1;33m)\u001b[0m\u001b[1;33m,\u001b[0m \u001b[1;36m0\u001b[0m\u001b[1;33m\u001b[0m\u001b[1;33m\u001b[0m\u001b[0m\n\u001b[0m\u001b[0;32m    383\u001b[0m \u001b[1;33m\u001b[0m\u001b[0m\n\u001b[0;32m    384\u001b[0m     \u001b[1;31m# Select filename, lineno, func_name to track frames with\u001b[0m\u001b[1;33m\u001b[0m\u001b[1;33m\u001b[0m\u001b[1;33m\u001b[0m\u001b[0m\n",
      "\u001b[1;31mTypeError\u001b[0m: object of type 'NoneType' has no len()"
     ]
    }
   ],
   "source": [
    "x_train = pd.read_csv(r'../input/satdrec/Train_Features.csv', index_col=0)\n",
    "y_train = pd.read_csv(r'../input/satdrec/Train_Labels.csv', index_col=0)\n",
    "x_test = pd.read_csv(r'../input/satdrec/Test_Features.csv', index_col=0)\n",
    "y_test = pd.read_csv(r'../input/satdrec/Test_Labels.csv', index_col=0)"
   ]
  },
  {
   "cell_type": "code",
   "execution_count": null,
   "metadata": {},
   "outputs": [],
   "source": [
    "\n",
    "\n",
    "def get_tail_label(df):\n",
    "    \"\"\"\n",
    "    Give tail label colums of the given target dataframe\n",
    "\n",
    "    args\n",
    "    df: pandas.DataFrame, target label df whose tail label has to identified\n",
    "\n",
    "    return\n",
    "    tail_label: list, a list containing column name of all the tail label\n",
    "    \"\"\"\n",
    "    columns = df.columns\n",
    "    n = len(columns)\n",
    "    irpl = np.zeros(n)\n",
    "    for column in range(n):\n",
    "        irpl[column] = df[columns[column]].value_counts()[1]\n",
    "    irpl = max(irpl)/irpl\n",
    "    mir = np.average(irpl)\n",
    "    tail_label = []\n",
    "    for i in range(n):\n",
    "        if irpl[i] > mir:\n",
    "            tail_label.append(columns[i])\n",
    "    return tail_label\n",
    "\n",
    "def get_index(df):\n",
    "    \"\"\"\n",
    "    give the index of all tail_label rows\n",
    "    args\n",
    "    df: pandas.DataFrame, target label df from which index for tail label has to identified\n",
    "\n",
    "    return\n",
    "    index: list, a list containing index number of all the tail label\n",
    "    \"\"\"\n",
    "    tail_labels = get_tail_label(df)\n",
    "    index = set()\n",
    "    for tail_label in tail_labels:\n",
    "        sub_index = set(df[df[tail_label]==1].index)\n",
    "        index = index.union(sub_index)\n",
    "    return list(index)\n",
    "\n",
    "def get_minority_instace(X, y):\n",
    "    \"\"\"\n",
    "    Give minority dataframe containing all the tail labels\n",
    "\n",
    "    args\n",
    "    X: pandas.DataFrame, the feature vector dataframe\n",
    "    y: pandas.DataFrame, the target vector dataframe\n",
    "\n",
    "    return\n",
    "    X_sub: pandas.DataFrame, the feature vector minority dataframe\n",
    "    y_sub: pandas.DataFrame, the target vector minority dataframe\n",
    "    \"\"\"\n",
    "    index = get_index(y)\n",
    "    X_sub = X[X.index.isin(index)].reset_index(drop = True)\n",
    "    y_sub = y[y.index.isin(index)].reset_index(drop = True)\n",
    "    return X_sub, y_sub\n",
    "\n",
    "def nearest_neighbour(X):\n",
    "    \"\"\"\n",
    "    Give index of 5 nearest neighbor of all the instance\n",
    "\n",
    "    args\n",
    "    X: np.array, array whose nearest neighbor has to find\n",
    "\n",
    "    return\n",
    "    indices: list of list, index of 5 NN of each element in X\n",
    "    \"\"\"\n",
    "    nbs=NearestNeighbors(n_neighbors=5,metric='euclidean',algorithm='kd_tree').fit(X)\n",
    "    euclidean,indices= nbs.kneighbors(X)\n",
    "    return indices\n",
    "\n",
    "def MLSMOTE(X,y, n_sample):\n",
    "    \"\"\"\n",
    "    Give the augmented data using MLSMOTE algorithm\n",
    "\n",
    "    args\n",
    "    X: pandas.DataFrame, input vector DataFrame\n",
    "    y: pandas.DataFrame, feature vector dataframe\n",
    "    n_sample: int, number of newly generated sample\n",
    "\n",
    "    return\n",
    "    new_X: pandas.DataFrame, augmented feature vector data\n",
    "    target: pandas.DataFrame, augmented target vector data\n",
    "    \"\"\"\n",
    "    indices2 = nearest_neighbour(X)\n",
    "    n = len(indices2)\n",
    "    new_X = np.zeros((n_sample, X.shape[1]))\n",
    "    target = np.zeros((n_sample, y.shape[1]))\n",
    "    for i in range(n_sample):\n",
    "        reference = random.randint(0,n-1)\n",
    "        neighbour = random.choice(indices2[reference,1:])\n",
    "        all_point = indices2[reference]\n",
    "        nn_df = y[y.index.isin(all_point)]\n",
    "        ser = nn_df.sum(axis = 0, skipna = True)\n",
    "        target[i] = np.array([1 if val>2 else 0 for val in ser])\n",
    "        ratio = random.random()\n",
    "        gap = X.loc[reference,:] - X.loc[neighbour,:]\n",
    "        new_X[i] = np.array(X.loc[reference,:] + ratio * gap)\n",
    "    new_X = pd.DataFrame(new_X, columns=X.columns)\n",
    "    target = pd.DataFrame(target, columns=y.columns)\n",
    "    new_X = pd.concat([X, new_X], axis=0)\n",
    "    target = pd.concat([y, target], axis=0)\n",
    "    return new_X, target"
   ]
  },
  {
   "cell_type": "code",
   "execution_count": null,
   "metadata": {},
   "outputs": [],
   "source": [
    "X_sub, y_sub = get_minority_instace(x_train, y_train)   #Getting minority instance of that datframe\n",
    "X_res,y_res =MLSMOTE(X_sub, y_sub, 1000)     #Applying MLSMOTE to augment the dataframe\n",
    "\n",
    "print(y_res.sum())\n",
    "print(\"-----------------------------\")\n",
    "\n",
    "print(y_train.sum())"
   ]
  },
  {
   "cell_type": "code",
   "execution_count": null,
   "metadata": {},
   "outputs": [],
   "source": [
    "input_dim = X_res.shape[1]  # Number of features\n",
    "\n",
    "model = Sequential()\n",
    "model.add(Dense(5000, input_dim=input_dim, activation='relu'))\n",
    "model.add(Dropout(0.5))\n",
    "model.add(Dense(600, activation='sigmoid'))\n",
    "model.add(Dropout(0.5))\n",
    "model.add(Dense(300, activation='sigmoid'))\n",
    "model.add(Dropout(0.5))\n",
    "model.add(Dense(100, activation=\"sigmoid\"))\n",
    "model.add(Dropout(0.5))\n",
    "model.add(Dense(60, activation=\"sigmoid\"))\n",
    "model.add(Dropout(0.5))\n",
    "model.add(Dense(40, activation=\"sigmoid\"))\n",
    "model.add(Dense(y_res.shape[1], activation='sigmoid'))\n",
    "\n",
    "\n",
    "\n",
    "model.compile(loss='binary_crossentropy', \n",
    "              optimizer='adam', \n",
    "              metrics=['binary_accuracy'])\n",
    "model.summary()\n",
    "\n",
    "\n",
    "\n",
    "history = model.fit(X_res, y_res,\n",
    "                    epochs=20,\n",
    "                    verbose=True,\n",
    "                    validation_data=(x_test, y_test),\n",
    "                    batch_size=10)\n",
    "\n",
    "\n",
    "loss, accuracy = model.evaluate(X_res, y_res, verbose=False)\n",
    "print(\"Training Accuracy: {:.4f}\".format(accuracy))\n",
    "loss, accuracy = model.evaluate(x_test, y_test, verbose=False)\n",
    "print(\"Testing Accuracy:  {:.4f}\".format(accuracy))"
   ]
  },
  {
   "cell_type": "code",
   "execution_count": null,
   "metadata": {},
   "outputs": [],
   "source": [
    "plot_history(history)\n"
   ]
  },
  {
   "cell_type": "code",
   "execution_count": null,
   "metadata": {},
   "outputs": [],
   "source": []
  }
 ],
 "metadata": {
  "kernelspec": {
   "display_name": "Python 3 (ipykernel)",
   "language": "python",
   "name": "python3"
  },
  "language_info": {
   "codemirror_mode": {
    "name": "ipython",
    "version": 3
   },
   "file_extension": ".py",
   "mimetype": "text/x-python",
   "name": "python",
   "nbconvert_exporter": "python",
   "pygments_lexer": "ipython3",
   "version": "3.8.12"
  }
 },
 "nbformat": 4,
 "nbformat_minor": 4
}
